Workbook

Sheet Resumen
A1: CITAJUSTA — PRODUCT BACKLOG v2.0 · RESUMEN
A2: Corte 17-10-2026 · HEAD 865a7d0 · Los valores se calculan con fórmulas sobre la hoja "Product Backlog" (columna E = estado, H = sprint de integración).
A4: Indicador | B4: Valor | C4: Fórmula | D4: Lectura
A5: HU registradas | B5: =COUNTIF('Product Backlog'!A:A,"HU-*") -> 44 | C5: COUNTIF(A:A,"HU-*") | D5: HU-001 a HU-044 (HU-044 registrada a posteriori el 17-10-2026).
A6: HU excluidas del alcance | B6: =COUNTIF('Product Backlog'!E:E,"Excluida*") -> 1 | C6: COUNTIF(E:E,"Excluida*") | D6: HU-043 WhatsApp, retirada el 15-10-2026.
A7: HU vigentes | B7: =B5-B6 -> 43 | C7: HU registradas − excluidas | D7: Base del avance por historias.
A8: HU Done | B8: =COUNTIFS('Product Backlog'!A:A,"HU-*",'Product Backlog'!E:E,"Done") -> 43 | C8: COUNTIFS(A:A,"HU-*",E:E,"Done") | D8: Integradas a main y verificadas.
A9: Avance por HU vigentes | B9: =B8/B7 -> 1 | C9: HU Done / HU vigentes | D9: El backlog funcional está completo; el cierre técnico (Sprint 9) se mide aparte.
A10: PBI de cierre técnico (Sprint 9) | B10: =COUNTIF('Product Backlog'!A:A,"PBI-S9-*") -> 10 | C10: COUNTIF(A:A,"PBI-S9-*") | D10: Docker, OpenAPI, hardening, CI, pruebas, documentación.
A11: PBI Sprint 9 Done | B11: =COUNTIFS('Product Backlog'!A:A,"PBI-S9-*",'Product Backlog'!E:E,"Done") -> 0 | C11: COUNTIFS(A:A,"PBI-S9-*",E:E,"Done") | D11: Ninguno cumple aún la DoD (Docker está preparado y verificado, pero no integrado).
A12: PBI Sprint 9 preparados sin integrar | B12: =COUNTIFS('Product Backlog'!A:A,"PBI-S9-*",'Product Backlog'!E:E,"Preparado*") -> 1 | C12: COUNTIFS(...,E:E,"Preparado*") | D12: PBI-S9-01 Docker/Compose: verificado el 17-10-2026 (anexo Propuesta_Docker), pendiente de integración.
A13: Avance total del backlog (HU vigentes + PBI Sprint 9) | B13: =(B8+B11)/(B7+B10) -> 0.81132075 | C13: (HU Done + PBI Done) / (HU vigentes + PBI) | D13: Medición derivada del backlog; si la propuesta Docker se integra por PR sube a 44/53 (83,0 %).
A14: Story Points registrados (HU-001 a HU-020) | B14: =SUM('Product Backlog'!F5:F58) -> 105 | C14: SUM(F:F) | D14: Sólo HU-001 a HU-020 tienen estimación histórica.
A15: Story Points Done | B15: =SUMIFS('Product Backlog'!F5:F58,'Product Backlog'!E5:E58,"Done") -> 105 | C15: SUMIFS(F:F,E:E,"Done") | D15: HU-021 en adelante: "Sin estimación registrada".
A18: Sprint | B18: HU según planificación (v1.10) | C18: HU según fecha de merge | D18: Observación
A19: Sprint 3 | B19: =COUNTIFS('Product Backlog'!A:A,"HU-*",'Product Backlog'!G:G,"Sprint 3") -> 2 | C19: =COUNTIFS('Product Backlog'!A:A,"HU-*",'Product Backlog'!H:H,"Sprint 3") -> 2
A20: Sprint 4 | B20: =COUNTIFS('Product Backlog'!A:A,"HU-*",'Product Backlog'!G:G,"Sprint 4") -> 5 | C20: =COUNTIFS('Product Backlog'!A:A,"HU-*",'Product Backlog'!H:H,"Sprint 4") -> 0 | D20: El Sprint 4 integró la base read-only (PR #15–#19); HU-003 y HU-012–015 se cerraron después.
A21: Sprint 5 | B21: =COUNTIFS('Product Backlog'!A:A,"HU-*",'Product Backlog'!G:G,"Sprint 5") -> 7 | C21: =COUNTIFS('Product Backlog'!A:A,"HU-*",'Product Backlog'!H:H,"Sprint 5") -> 6
A22: Sprint 6 | B22: =COUNTIFS('Product Backlog'!A:A,"HU-*",'Product Backlog'!G:G,"Sprint 6") -> 8 | C22: =COUNTIFS('Product Backlog'!A:A,"HU-*",'Product Backlog'!H:H,"Sprint 6") -> 16 | D22: Concentra HU documentadas en Sprints 4, 5 y 7 (ver hoja Cambios de alcance y libro de Sprint Backlogs).
A23: Sprint 7 | B23: =COUNTIFS('Product Backlog'!A:A,"HU-*",'Product Backlog'!G:G,"Sprint 7") -> 16 | C23: =COUNTIFS('Product Backlog'!A:A,"HU-*",'Product Backlog'!H:H,"Sprint 7") -> 14
A24: Sprint 8 | B24: =COUNTIFS('Product Backlog'!A:A,"HU-*",'Product Backlog'!G:G,"Sprint 8") -> 5 | C24: =COUNTIFS('Product Backlog'!A:A,"HU-*",'Product Backlog'!H:H,"Sprint 8") -> 4 | D24: Plan incluye HU-043 (excluida).
A25: Sprint 9 | B25: =COUNTIFS('Product Backlog'!A:A,"HU-*",'Product Backlog'!G:G,"Sprint 9") -> 0 | C25: =COUNTIFS('Product Backlog'!A:A,"HU-*",'Product Backlog'!H:H,"Sprint 9") -> 1 | D25: HU-044 registrada a posteriori; además 10 PBI de cierre técnico.
A27: Interpretación: el 100 % por historias indica que todo el alcance funcional vigente quedó integrado. No equivale al avance del proyecto Capstone: falta el cierre técnico del Sprint 9 (integración de la propuesta Docker, OpenAPI, hardening, CI, pruebas formales) y la validación documental. Las estimaciones del equipo del 15-10-2026 (70 % general / 80 % técnico) no se calcularon desde el backlog; la medición derivada del backlog al 17-10-2026 es 81,1 %.

Sheet Product Backlog
A1: CITAJUSTA — PRODUCT BACKLOG PRIORIZADO · VERSIÓN 2.0
A2: Corte 17-10-2026. HU-001 a HU-042 y HU-044 Done; HU-043 excluida; 10 PBI de cierre técnico del Sprint 9. Fechas de merge y PR verificados en el historial git local (HEAD 865a7d0). Se conserva la redacción y los criterios de la v1.10.
A4: ID | B4: Épica | C4: Historia de usuario / elemento | D4: Alias | E4: Estado | F4: Story Points | G4: Sprint planificado (v1.10) | H4: Sprint de integración (fecha de merge) | I4: ¿Coincide plan e integración? | J4: Fecha de merge | K4: Prioridad | L4: RF | M4: Alcance | N4: Criterios de aceptación (resumen) | O4: Evidencia / rama (v1.10) | P4: Pull Request | Q4: Issue GitHub | R4: Comentarios v1.10 | S4: Observación v2.0
A5: HU-001 | B5: EP-01 Cuenta y acceso | C5: Como usuario final, quiero crear una cuenta, para utilizar CitaJusta y administrar mis citas. | D5: Registro de usuario | E5: Done | F5: 3 | G5: Sprint 3 | H5: Sprint 3 | I5: Sí | J5: 2026-08-30 | K5: Alta | L5: RF-001 | M5: MVP | N5: El sistema valida campos obligatorios y formatos. • No permite registrar un correo ya utilizado. • La contraseña cumple la política definida y nunca se almacena en texto plano. | O5: feat/auth-foundation | P5: #13 | Q5: Pendiente de vincular | R5: Registro implementado y probado en Auth.
A6: HU-002 | B6: EP-01 Cuenta y acceso | C6: Como usuario, quiero iniciar sesión de forma segura, para acceder únicamente a las funciones que me corresponden. | D6: Inicio de sesión | E6: Done | F6: 3 | G6: Sprint 3 | H6: Sprint 3 | I6: Sí | J6: 2026-08-30 | K6: Crítica | L6: RF-002 | M6: MVP | N6: Credenciales válidas permiten acceder. • Credenciales inválidas no revelan si el correo existe. • El backend valida autenticación y rol para recursos protegidos. | O6: feat/auth-foundation / feat/rbac-institution-context | P6: #13, #14 | Q6: Pendiente de vincular | R6: Login, refresh rotativo y logout implementados y probados.
A7: HU-003 | B7: EP-02 Citas | C7: Como usuario, quiero buscar citas por servicio, sede y fecha o preferencia, para encontrar una atención compatible con mis necesidades. | D7: Buscar citas | E7: Done | F7: 5 | G7: Sprint 4 | H7: Sprint 5 | I7: No | J7: 2026-09-09 | K7: Crítica | L7: RF-011 / RF-012 | M7: MVP | N7: La búsqueda exige al menos un servicio. • Los resultados respetan filtros válidos de sede y fecha/preferencia. • No se muestran cupos bloqueados, ocupados o fuera de disponibilidad. | O7: feat/catalog-read-foundation / feat/availability-read-foundation / feat/web-api-integration · PR #43 | P7: #16, #17, #18 (31-08); cierre funcional #43 | Q7: S5-T05 · PR #43 | R7: Búsqueda funcional completada de punta a punta: institución/sede/servicio, consulta de disponibilidad y resultados reales en Web. Cierre funcional realizado en Sprint 5 sobre la base backend iniciada en Sprint 4; validación Web/API/PostgreSQL E2E 13/13 y revisión manual. | S7: Planificada en Sprint 4 (base backend #16–#18, 31-08); el cierre funcional ocurrió en Sprint 5 con la integración Web (#43).
A8: HU-004 | B8: EP-02 Citas | C8: Como usuario, quiero reservar un cupo disponible, para asegurar una atención en el horario seleccionado. | D8: Reservar una cita | E8: Done | F8: 5 | G8: Sprint 5 | H8: Sprint 5 | I8: Sí | J8: 2026-09-06 | K8: Crítica | L8: RF-013 | M8: MVP | N8: El backend revalida el cupo dentro de una transacción Serializable. • Una reserva exitosa crea una sola cita activa con estado AGENDADA y origen WEB interno. • La actualización condicional AVAILABLE→RESERVED usa lockVersion. • UNIQUE(citas.cupo_id) evita doble asignación. • Concurrencia real verificada: un 201, un 409 y una sola cita. | O8: feat/appointments-booking-foundation · commit 7a6a80e · merge a main 9b3e5a7 | P8: #35 | Q8: PR HU-004 fusionado | R8: Reserva transaccional implementada y validada. POST /api/v1/appointments; estado inicial AGENDADA; origen WEB interno; transacción Serializable; AVAILABLE→RESERVED con lockVersion; UNIQUE(citas.cupo_id) como segunda defensa; historial inicial. Validación final: 88/88 unitarios, E2E checkpoint 1/1 y E2E appointments 8/8.
A9: HU-005 | B9: EP-02 Citas | C9: Como usuario, quiero visualizar mis citas y su estado, para saber cuándo debo asistir y qué acciones tengo disponibles. | D9: Consultar mis citas | E9: Done | F9: 3 | G9: Sprint 5 | H9: Sprint 5 | I9: Sí | J9: 2026-09-07 | K9: Alta | L9: RF-014 | M9: MVP | N9: El usuario sólo ve sus propias citas. • Se muestran fecha, hora, servicio, sede, profesional y estado aplicable. • Las acciones disponibles dependen del estado y permisos. | O9: commit 89d15a8 · GET /api/v1/appointments/me | P9: Sin PR: commit directo a main 89d15a8 | Q9: HU-005 creada en GitHub Projects | R9: Consulta autenticada de citas propias implementada. Aislamiento por AuthenticatedPrincipal, DTO público controlado, orden startsAt ASC/id ASC. Validación al cierre de HU-005: 96/96 unitarios, appointments E2E 14/14 y checkpoint 1/1. | S9: Única HU integrada sin Pull Request (commit directo a main). La DoD v1.0 exige PR para toda integración.
A10: HU-006 | B10: EP-02 Citas | C10: Como usuario, quiero cancelar una cita que no podré utilizar, para liberar el cupo y mantener mi agenda actualizada. | D10: Cancelar una cita | E10: Done | F10: 5 | G10: Sprint 5 | H10: Sprint 5 | I10: Sí | J10: 2026-09-07 | K10: Crítica | L10: RF-015 | M10: MVP | N10: Sólo el titular o un rol autorizado puede cancelar. • La cancelación cambia el estado de la cita y queda auditada. • Si el cupo es reutilizable, queda disponible para el proceso de reasignación. | O10: feat/appointments-cancellation · commit 9c62153 · PR #37 | P10: #37 | Q10: #32 | R10: Cancelación transaccional e idempotente implementada: AGENDADA → CANCELADA y AgendaSlot RESERVED → RELEASED, sin volver a AVAILABLE. Concurrencia validada 200/200 sin doble efecto. Validación actual: 114/114 unitarios, appointments E2E 22/22, checkpoint 1/1 y build aprobado.
A11: HU-007 | B11: EP-03 Lista de espera | C11: Como usuario, quiero ingresar a una lista de espera cuando no haya disponibilidad adecuada, para tener la posibilidad de recibir un cupo que se libere. | D11: Ingresar a lista de espera | E11: Done | F11: 5 | G11: Sprint 5 | H11: Sprint 5 | I11: Sí | J11: 2026-09-10 | K11: Crítica | L11: RF-018 / RF-019 | M11: MVP | N11: Sólo se permite una espera activa equivalente cuando así lo defina la regla de negocio. • Se registran servicio, sede/preferencias y fecha de ingreso. • El usuario puede consultar el estado de la espera. | O11: feat/waitlist-entry | P11: #46 | Q11: HU-007 (tarjeta Kanban) | R11: Alta y consulta de lista de espera implementadas y validadas contra PostgreSQL real.
A12: HU-008 | B12: EP-03 Lista de espera | C12: Como usuario, quiero indicar y modificar mis días, horarios y sede preferidos, para recibir solamente ofertas que pueda utilizar. | D12: Gestionar preferencias de espera | E12: Done | F12: 5 | G12: Sprint 5 | H12: Sprint 5 | I12: Sí | J12: 2026-09-10 | K12: Alta | L12: RF-019 / RF-021 | M12: MVP | N12: Las preferencias deben usar valores válidos. • Los cambios aplican a futuras evaluaciones de compatibilidad. • El usuario puede retirarse de una espera activa y el cambio queda persistido. | O12: feat/waitlist-preferences | P12: #58 | Q12: HU-008 (tarjeta Kanban) | R12: Preferencias y retiro implementados; E2E HU-007/HU-008 real 24/24 PASS.
A13: HU-009 | B13: EP-07 Ofertas | C13: Como usuario en lista de espera, quiero recibir una oferta cuando se libere un cupo compatible, para decidir si deseo tomarlo. | D13: Recibir oferta de cupo liberado | E13: Done | F13: 8 | G13: Sprint 6 | H13: Sprint 6 | I13: Sí | J13: 2026-09-10 | K13: Crítica | L13: RF-022 a RF-027 / RF-034 | M13: MVP | N13: La oferta sólo se genera para un candidato compatible. • La oferta posee fecha/hora de expiración persistida. • El usuario es notificado dentro de CitaJusta. | O13: feat/reassignment-offers | P13: #59 | Q13: HU-009 (tarjeta Kanban) | R13: Generación de oferta, ranking/snapshot y TTL implementados en backend.
A14: HU-010 | B14: EP-07 Ofertas | C14: Como usuario, quiero aceptar una oferta vigente, para obtener el cupo liberado de manera segura. | D14: Aceptar una oferta | E14: Done | F14: 8 | G14: Sprint 6 | H14: Sprint 6 | I14: Sí | J14: 2026-09-10 | K14: Crítica | L14: RF-027 | M14: MVP | N14: Sólo el destinatario puede aceptar la oferta. • La oferta debe estar vigente y el cupo disponible. • La aceptación se ejecuta transaccionalmente. | O14: feat/accept-reassignment-offer | P14: #60 | Q14: HU-010 (tarjeta Kanban) | R14: Aceptación transaccional e idempotente implementada con transferencia segura de la cita.
A15: HU-011 | B15: EP-07 Ofertas | C15: Como usuario, quiero rechazar una oferta que no puedo utilizar, para que el sistema pueda continuar con otro candidato. | D15: Rechazar una oferta | E15: Done | F15: 3 | G15: Sprint 6 | H15: Sprint 6 | I15: Sí | J15: 2026-09-10 | K15: Alta | L15: RF-028 | M15: MVP | N15: Sólo el destinatario puede rechazar. • La oferta cambia a estado rechazado. • El cupo puede continuar con el siguiente candidato válido. | O15: feat/reject-reassignment-offer | P15: #61 | Q15: HU-011 (tarjeta Kanban) | R15: Rechazo y continuidad/exhaustión del flujo implementados.
A16: HU-012 | B16: EP-05 Administración | C16: Como administrador institucional, quiero administrar sedes y servicios, para configurar correctamente la oferta de atención de mi institución. | D16: Gestionar servicios y sedes | E16: Done | F16: 5 | G16: Sprint 4 | H16: Sprint 6 | I16: No | J16: 2026-09-13 | K16: Alta | L16: RF-005 a RF-007 | M16: MVP | N16: Sólo roles autorizados pueden crear o modificar datos institucionales. • Una sede pertenece a una institución válida. • Un servicio puede activarse o desactivarse sin borrar su historial. | O16: feat/catalog-administration | P16: #68 | Q16: HU-012 (tarjeta Kanban) | R16: Administración de sedes/servicios implementada con permisos y activación/desactivación. | S16: Documentada en Sprint 4, pero se integró el 13-09, después del cierre del Sprint 4 (07-09). El burndown del Sprint 4 sólo cubre los PR #15–#19.
A17: HU-013 | B17: EP-05 Administración | C17: Como administrador institucional, quiero registrar profesionales y asociarlos a servicios y sedes, para construir la agenda institucional. | D17: Gestionar profesionales | E17: Done | F17: 5 | G17: Sprint 4 | H17: Sprint 6 | I17: No | J17: 2026-09-14 | K17: Alta | L17: RF-008 | M17: MVP | N17: El profesional se asocia a una institución y a servicios válidos. • No se crean asociaciones duplicadas equivalentes. • Los cambios relevantes quedan auditados. | O17: feat/professional-administration | P17: #71 | Q17: HU-013 (tarjeta Kanban) | R17: Administración de profesionales y asociaciones implementada. | S17: Documentada en Sprint 4; integrada el 14-09, dentro de la ventana del Sprint 6.
A18: HU-014 | B18: EP-04 Agenda | C18: Como usuario autorizado, quiero configurar disponibilidad, bloqueos e indisponibilidades, para evitar que se ofrezcan horarios no atendibles. | D18: Configurar disponibilidad | E18: Done | F18: 8 | G18: Sprint 4 | H18: Sprint 6 | I18: No | J18: 2026-09-14 | K18: Crítica | L18: RF-009 | M18: MVP | N18: No se aceptan rangos inválidos o superpuestos cuando generen conflicto. • Los bloqueos impiden nuevas reservas en el periodo afectado. • La agenda refleja los cambios de disponibilidad. | O18: feat/availability-administration | P18: #74 | Q18: HU-014 (tarjeta Kanban) | R18: Disponibilidad, materialización de cupos y bloqueos implementados. | S18: Documentada en Sprint 4; integrada el 14-09, dentro de la ventana del Sprint 6.
A19: HU-015 | B19: EP-04 Agenda | C19: Como funcionario, quiero consultar la agenda por fecha, sede, servicio, profesional y estado, para gestionar la operación diaria. | D19: Consultar agenda institucional | E19: Done | F19: 5 | G19: Sprint 4 | H19: Sprint 6 | I19: No | J19: 2026-09-14 | K19: Alta | L19: RF-010 | M19: MVP | N19: La agenda puede filtrarse por los criterios definidos. • Cada cita muestra estado y datos operativos relevantes. • El usuario sólo consulta sedes/recursos dentro de su ámbito autorizado. | O19: feat/institutional-agenda | P19: #76 | Q19: HU-015 (tarjeta Kanban) | R19: Agenda institucional con filtros y trazabilidad de estados implementada. | S19: Documentada en Sprint 4; integrada el 14-09, dentro de la ventana del Sprint 6.
A20: HU-016 | B20: EP-06 Reasignación | C20: Como funcionario autorizado, quiero visualizar el cupo liberado, candidatos evaluados, oferta y estado del flujo, para supervisar la reasignación automática. | D20: Supervisar una reasignación | E20: Done | F20: 8 | G20: Sprint 6 | H20: Sprint 6 | I20: Sí | J20: 2026-09-13 | K20: Crítica | L20: RF-032 / RF-033 | M20: MVP | N20: El flujo muestra al menos cupo, candidatos, oferta y estado actual. • La vista distingue operación automática de intervención manual autorizada. • Cada paso crítico posee trazabilidad. | O20: feat/reassignment-supervision | P20: #65 | Q20: HU-016 (tarjeta Kanban) | R20: Consulta read-only de reasignación con trazabilidad y política implementada.
A21: HU-017 | B21: EP-08 Operación | C21: Como funcionario o profesional autorizado, quiero registrar asistencia o inasistencia, para mantener el historial operativo y apoyar las reglas institucionales. | D21: Registrar asistencia e inasistencia | E21: Done | F21: 3 | G21: Sprint 5 | H21: Sprint 6 | I21: No | J21: 2026-09-15 | K21: Media | L21: RF-017 | M21: Objetivo | N21: Sólo roles autorizados registran asistencia/inasistencia. • No se registra asistencia sobre una cita cancelada. • El cambio queda persistido y auditado. | O21: feat/appointment-attendance | P21: #79 | Q21: HU-017 (tarjeta Kanban) | R21: Registro de ATENDIDA/INASISTENCIA implementado con control de transiciones. | S21: Documentada en Sprint 5; integrada el 15-09 y no figura entre las 8 tareas del Sprint 5.
A22: HU-018 | B22: EP-05 Administración | C22: Como administrador institucional, quiero configurar parámetros permitidos de priorización, para adaptar la reasignación a las políticas de la institución. | D22: Configurar reglas de reasignación | E22: Done | F22: 8 | G22: Sprint 6 | H22: Sprint 6 | I22: Sí | J22: 2026-09-15 | K22: Alta | L22: Pendiente trazabilidad RF | M22: Objetivo | N22: Sólo administradores autorizados pueden cambiar parámetros. • Los valores deben respetar límites definidos por el sistema. • Los cambios quedan versionados o auditados y no alteran retroactivamente decisiones cerradas. | O22: feat/reassignment-policy | P22: #81 | Q22: HU-018 (tarjeta Kanban) | R22: Políticas versionadas e inmutables de reasignación implementadas. | S22: Sin RF propio en v1.10; se relaciona con RF-025 (ordenar candidatos según reglas definidas).
A23: HU-019 | B23: EP-09 Reportes | C23: Como administrador, quiero consultar indicadores de cancelaciones, ofertas y cupos recuperados, para evaluar el desempeño de la agenda. | D23: Consultar indicadores | E23: Done | F23: 5 | G23: Sprint 7 | H23: Sprint 6 | I23: No | J23: 2026-09-16 | K23: Media | L23: RF-037 | M23: Objetivo | N23: Los indicadores se calculan a partir de datos persistidos. • Los filtros respetan el ámbito institucional. • Los resultados distinguen cancelaciones, ofertas, aceptaciones, expiraciones y cupos recuperados cuando corresponda. | O23: feat/reports-indicators · PR #84 | P23: #84 | Q23: HU-019 (tarjeta Kanban) | R23: Indicadores institucionales implementados y validados. | S23: Documentada en Sprint 7; integrada el 16-09 (ventana Sprint 6) como prerrequisito institucional.
A24: HU-020 | B24: EP-10 Auditoría | C24: Como auditor autorizado, quiero consultar la bitácora de operaciones relevantes, para reconstruir qué ocurrió, cuándo y por quién. | D24: Consultar trazabilidad | E24: Done | F24: 5 | G24: Sprint 7 | H24: Sprint 6 | I24: No | J24: 2026-09-16 | K24: Alta | L24: RF-036 | M24: Objetivo | N24: El auditor posee acceso de lectura sin capacidad de alterar eventos. • La bitácora permite identificar actor/sistema, fecha, acción y recurso afectado según corresponda. • Los logs no exponen secretos o credenciales. | O24: feat/audit-trail · PR #86 | P24: #86 | Q24: HU-020 (tarjeta Kanban) | R24: Auditoría read-only e instrumentación de eventos relevantes implementadas y validadas. | S24: Documentada en Sprint 7; integrada el 16-09 (ventana Sprint 6) como prerrequisito institucional.
A25: HU-021 | B25: EP-03 Lista de espera | C25: Como usuario de CitaJusta, quiero gestionar desde la Web mi participación en listas de espera y sus preferencias, para inscribirme, ajustar mis condiciones de atención y retirarme cuando corresponda. | D25: Gestionar lista de espera y preferencias desde la Web | E25: Done | F25: Sin estimación registrada | G25: Sprint 5 | H25: Sprint 6 | I25: No | J25: 2026-09-17 | K25: Alta | L25: HU-007 / HU-008 Web | M25: MVP | N25: El usuario autenticado puede consultar e ingresar a listas válidas. • Puede configurar días, rangos y sedes preferidas. • Puede retirarse. • La UI usa respuestas reales y no replica ranking/elegibilidad. | O25: feat/web-waitlist · PR #89 · merge c291d17 | P25: #89 | Q25: HU-021 (tarjeta Kanban) | R25: Validación real Web + API + PostgreSQL: alta ACTIVE, preferencias persistentes y retiro. Web 56/56; development/seed 11/11; Waitlist E2E 24/24. | S25: Documentada en Sprint 5; integrada el 17-09. La Revisión Daily (23-09) la cuenta entre las 10 tareas del Sprint 6.
A26: HU-022 | B26: EP-07 Ofertas | C26: Como usuario de CitaJusta, quiero visualizar y responder desde la Web las ofertas de reasignación que reciba, para aceptar una nueva hora compatible o rechazarla de forma segura. | D26: Gestionar ofertas de reasignación desde la Web | E26: Done | F26: Sin estimación registrada | G26: Sprint 6 | H26: Sprint 6 | I26: Sí | J26: 2026-09-20 | K26: Crítica | L26: HU-009 / HU-010 / HU-011 Web | M26: MVP | N26: La Web muestra ofertas reales y su expiresAt. • Permite aceptar/rechazar mediante los endpoints reales. • La aceptación transfiere la cita existente. • El rechazo no crea una cita. • El cliente no recalcula elegibilidad ni ranking. | O26: feat/web-reassignment-offers · PR #93 · merge 5701ab7 | P26: #93 | Q26: HU-022 (tarjeta Kanban) | R26: Validación completa Web + API + PostgreSQL: ACCEPT transfirió cita AGENDADA; REJECT no creó cita; oferta vencida deshabilitada sin mutación desde el cliente.
A27: HU-023 | B27: EP-07 Ofertas | C27: Como sistema CitaJusta, quiero expirar automáticamente las ofertas vencidas y continuar con el siguiente candidato elegible, para recuperar cupos liberados sin depender de intervención manual. | D27: Automatizar expiración y continuidad de reasignación | E27: Done | F27: Sin estimación registrada | G27: Sprint 6 | H27: Sprint 6 | I27: Sí | J27: 2026-09-21 | K27: Crítica | L27: RF-029 / RF-030 / RF-036 | M27: MVP | N27: Una oferta PENDING vencida pasa de forma persistente a EXPIRED. • La continuidad genera como máximo una siguiente oferta. • Sin candidatos el proceso queda EXHAUSTED. • Cupo/contexto inutilizable cierra CANCELLED. • La operación es idempotente, transaccional y segura ante concurrencia. | O27: feat/automatic-offer-expiration · PR #96 · merge 109b1c9 | P27: #96 | Q27: HU-023 (tarjeta Kanban) | R27: Runner interno sin dependencias nuevas. Auditoría OFFER_EXPIRED. Validación: API 368/368; E2E expiración 10/10; reasignaciones 20/20; audit 11/11; policy 13/13; reports 15/15; checkpoint 1/1.
A28: HU-024 | B28: EP-11 Notificaciones | C28: Como usuario de CitaJusta, quiero recibir y consultar notificaciones internas sobre eventos importantes de mis citas, lista de espera y ofertas, para mantenerme informado sin depender de servicios externos. | D28: Implementar notificaciones internas | E28: Done | F28: Sin estimación registrada | G28: Sprint 6 | H28: Sprint 6 | I28: Sí | J28: 2026-09-21 | K28: Alta | L28: RF-034 | M28: MVP | N28: Las notificaciones se persisten dentro de las transacciones reales del dominio. • Sólo el destinatario autenticado puede consultarlas o marcarlas como leídas. • Reintentos idempotentes no generan duplicados. • La Web muestra contador, listado y lectura persistente. | O28: feat/internal-notifications · PR #99 · merge b1bff30 | P28: #99 | Q28: HU-024 (tarjeta Kanban) | R28: Ocho eventos integrados. API /notifications/me + unread-count + read. Web /notificaciones. Validación: nuevos API 6/6; E2E notifications 8/8; API dirigida 157/157; regresión crítica 87/87; Web 83/83; prueba manual de lectura y logout/login PASS.
A29: HU-025 | B29: EP-06 Reasignación | C29: Como sistema CitaJusta, quiero iniciar automáticamente la reasignación cuando una cancelación libera un cupo reutilizable, para ofrecerlo a candidatos compatibles sin intervención administrativa. | D29: Iniciar reasignación automática tras cancelación | E29: Done | F29: Sin estimación registrada | G29: Sprint 7 | H29: Sprint 7 | I29: Sí | J29: 2026-09-22 | K29: Crítica | L29: Refuerzo RF-022 a RF-030 | M29: MVP | N29: Una cancelación que libera un cupo reutilizable inicia la reasignación en la misma transacción. • No crea procesos/ofertas duplicados. • Sin candidatos elegibles queda EXHAUSTED. • Cupos no reutilizables permiten completar la cancelación sin procesos parciales. | O29: feat/automatic-reassignment-start · PR #105 · merge ea33e9f | P29: #105 | Q29: #103 | R29: Validación: API 390/390; E2E automatic-start 8/8; build y regresión relacionada PASS. Inicio automático auditado como SYSTEM y cancelación como USER.
A30: HU-026 | B30: EP-02 Citas | C30: Como usuario de CitaJusta, quiero elegir una fecha específica o una búsqueda flexible, para encontrar disponibilidad de acuerdo con el día en que necesito atenderme. | D30: Buscar disponibilidad por fecha específica | E30: Done | F30: Sin estimación registrada | G30: Sprint 7 | H30: Sprint 7 | I30: Sí | J30: 2026-09-22 | K30: Alta | L30: RF-011 / RF-012 | M30: MVP | N30: Permite Fecha específica mediante calendario o modo flexible 7/14/30 días. • Rechaza fechas pasadas. • Hoy inicia desde la hora actual. • Respeta calendario local y cambios DST. • Mantiene el mismo contrato from/to del backend. | O30: feat/availability-date-search · PR #107 · merge ec427a4 | P30: #107 | Q30: HU-026 (tarjeta Kanban) | R30: Validación: fechas 10/10; UI 16/16; Web 95/95; typecheck/build PASS. Prueba manual: 4 cupos reales coincidentes entre búsqueda flexible y fecha específica.
A31: HU-027 | B31: EP-12 Desktop institucional | C31: Inicializar la aplicación institucional de escritorio con Tauri + React + TypeScript para disponer de una base nativa que consuma la misma API REST de CitaJusta. | D31: Inicializar aplicación Desktop institucional con Tauri | E31: Done | F31: Sin estimación registrada | G31: Sprint 7 | H31: Sprint 7 | I31: Sí | J31: 2026-09-22 | K31: Alta | L31: Fundación Desktop / interfaz institucional | M31: Objetivo | N31: Existe apps/desktop dentro del monorepo. • Tauri 2 + React/Vite/TypeScript compila y abre correctamente. • La shell institucional queda preparada sin duplicar reglas de negocio en Rust/Tauri. | O31: feat/desktop-tauri-foundation · commit 01ff1b1 · PR #112 · merge 6adab82 | P31: #112 | Q31: HU-027 (tarjeta Kanban) | R31: Fundación Desktop creada y validada con build frontend, cargo check y ejecución nativa Tauri.
A32: HU-028 | B32: EP-12 Desktop institucional | C32: Como usuario institucional, quiero iniciar sesión de forma segura en CitaJusta Desktop, para acceder a la API con mi contexto autorizado sin persistir tokens de forma insegura. | D32: Autenticación Desktop y client-core compartido | E32: Done | F32: Sin estimación registrada | G32: Sprint 7 | H32: Sprint 7 | I32: Sí | J32: 2026-09-22 | K32: Crítica | L32: Auth Desktop / cliente compartido | M32: Objetivo | N32: Login real contra API. • Perfil/contexto provienen del backend. • Tokens permanecen sólo en memoria. • Web y Desktop comparten HTTP/sesión mediante @citajusta/client-core. • Logout elimina la sesión local. | O32: feat/desktop-auth-api · commit 46fb85f · PR #113 · merge ae151b3 | P32: #113 | Q32: HU-028 (tarjeta Kanban) | R32: Validación: Web 95/95; Desktop 7/7; client-core 2/2; builds y cargo check PASS; login/logout manual en Tauri PASS.
A33: HU-029 | B33: EP-12 Desktop institucional | C33: Como usuario institucional autorizado, quiero gestionar las sedes y servicios de mi institución desde CitaJusta Desktop, para mantener actualizado el catálogo institucional utilizado por agenda, profesionales, disponibilidad y procesos de atención. | D33: Gestionar sedes y servicios desde Desktop | E33: Done | F33: Sin estimación registrada | G33: Sprint 7 | H33: Sprint 7 | I33: Sí | J33: 2026-09-23 | K33: Alta | L33: HU-012 Desktop / RBAC administrativo | M33: Objetivo | N33: Lecturas administrativas respetan tenant y scope. • Crear/editar/activar/inactivar sedes y servicios usa permisos explícitos. • Servicios administran branchIds y categorías reales. • GET públicos existentes conservan su contrato. | O33: feat/desktop-branch-service-management · commit f58c742 · merge e1cdb2e | P33: #118 | Q33: HU-029 (tarjeta Kanban) | R33: Validación: API 394/394; backend enfocado 34/34; E2E catálogo 15/15; Web 95/95; Desktop 16/16; client-core 4/4; Prisma/build/cargo/diff PASS y prueba manual Tauri/PostgreSQL completa. | S33: v1.10 citaba sólo commits; el merge e1cdb2e corresponde al PR #118.
A34: HU-030 | B34: EP-12 Desktop institucional | C34: Como administrador institucional autorizado, quiero gestionar profesionales desde CitaJusta Desktop, para mantener perfiles y asociaciones de atención desde la aplicación institucional. | D34: Gestionar profesionales desde Desktop | E34: Done | F34: Sin estimación registrada | G34: Sprint 7 | H34: Sprint 7 | I34: Sí | J34: 2026-09-23 | K34: Alta | L34: HU-013 Desktop / RBAC administrativo | M34: Objetivo | N34: La lista administrativa respeta institución y permisos. • El alta parte de una cuenta ACTIVE existente obtenida por búsqueda exacta. • La edición conserva userId y permite asociaciones/estado según la API. • Desktop no crea cuentas, credenciales ni roles. | O34: commit 7fac74a · feat: add desktop professional management | P34: #123 | Q34: HU-030 (tarjeta Kanban) | R34: Desktop Profesionales reutiliza HU-013 y catálogos reales; lectura/escritura separadas por permisos y validación institucional. | S34: v1.10 citaba sólo el commit 7fac74a; se agrega el PR #123.
A35: HU-031 | B35: EP-12 Desktop institucional | C35: Como funcionario institucional autorizado, quiero consultar la agenda diaria desde CitaJusta Desktop, para gestionar la operación con filtros y contexto real. | D35: Consultar agenda institucional desde Desktop | E35: Done | F35: Sin estimación registrada | G35: Sprint 7 | H35: Sprint 7 | I35: Sí | J35: 2026-09-24 | K35: Alta | L35: HU-015 Desktop / agenda.read | M35: Objetivo | N35: Consulta read-only de GET /api/v1/agenda. • Fecha obligatoria y filtros opcionales de sede, servicio, profesional y estado. • La sede contextual queda fija. • Las horas usan la zona institucional y no se inventan datos ni mutaciones. | O35: commit 5c60ac9 · feat: add desktop institutional agenda | P35: #126 | Q35: HU-031 (tarjeta Kanban) | R35: Agenda Desktop reutiliza la API HU-015, catálogos autenticados y protección frente a respuestas obsoletas. | S35: v1.10 citaba sólo el commit 5c60ac9; se agrega el PR #126.
A36: HU-032 | B36: EP-12 Desktop institucional | C36: Como usuario institucional autorizado, quiero consultar y gestionar disponibilidad y bloqueos desde CitaJusta Desktop, para mantener horarios atendibles sin duplicar reglas del backend. | D36: Gestionar disponibilidad y bloqueos desde Desktop | E36: Done | F36: Sin estimación registrada | G36: Sprint 7 | H36: Sprint 7 | I36: Sí | J36: 2026-09-26 | K36: Alta | L36: HU-014 Desktop / availability.* | M36: Objetivo | N36: Permisos independientes para leer, crear, actualizar y bloquear. • Usa la zona horaria institucional. • La sede contextual queda fija. • No edita/elimina bloqueos ni inventa AttentionPoint. • Escrituras reales no se reintentan automáticamente. | O36: commit 7644892 · feat: add desktop availability management | P36: #129 | Q36: HU-032 (tarjeta Kanban) | R36: Desktop reutiliza HU-014 y agrega lecturas administrativas controladas para disponibilidad/bloqueos con aislamiento institucional. | S36: v1.10 citaba sólo el commit 7644892; se agrega el PR #129.
A37: HU-033 | B37: EP-12 Desktop institucional | C37: Como funcionario o profesional autorizado, quiero registrar asistencia o inasistencia desde CitaJusta Desktop, para mantener actualizado el resultado operativo de las citas. | D37: Registrar asistencia e inasistencia desde Desktop | E37: Done | F37: Sin estimación registrada | G37: Sprint 7 | H37: Sprint 7 | I37: Sí | J37: 2026-09-28 | K37: Alta | L37: HU-017 Desktop / appointments.attendance | M37: Objetivo | N37: La consulta requiere agenda.read y las acciones requieren appointments.attendance. • Sólo citas AGENDADA ofrecen ATENDIDA/INASISTENCIA. • El body contiene únicamente el nuevo estado. • Estados finales o contradictorios no se reabren ni se fuerzan desde la UI. | O37: commit 511a3dd · feat: add desktop attendance management | P37: #133 | Q37: HU-033 (tarjeta Kanban) | R37: Asistencia Desktop reutiliza agenda HU-031 y endpoint HU-017; conserva contexto, filtros y feedback controlado. | S37: v1.10 citaba sólo el commit 511a3dd; se agrega el PR #133.
A38: HU-034 | B38: EP-12 Desktop institucional | C38: Como usuario institucional, quiero una interfaz Desktop visualmente consistente y accesible, para operar los módulos reales con navegación y estados claros. | D38: Modernizar sistema visual institucional Desktop | E38: Done | F38: Sin estimación registrada | G38: Sprint 7 | H38: Sprint 7 | I38: Sí | J38: 2026-09-28 | K38: Media | L38: UX institucional Desktop / transversal | M38: Objetivo | N38: Tokens y superficies compartidas. • Navegación agrupa Catálogo, Operación y Análisis. • Inicio utiliza accesos reales y no estadísticas simuladas. • Estados, formularios, teclado y ventana reducida conservan el comportamiento funcional existente. | O38: feat/desktop-visual-redesign · commit eef2153 · PR #135 · merge 056ba2b | P38: #135 | Q38: HU-034 (tarjeta Kanban) | R38: Rediseño visual transversal sin cambiar reglas de negocio, permisos ni contratos de API.
A39: HU-035 | B39: EP-07 Ofertas | C39: Como usuario Web que recibe ofertas de reasignación, quiero una experiencia más clara y moderna, para comprender su estado y responder con menor fricción. | D39: Modernizar UX de ofertas de reasignación Web | E39: Done | F39: Sin estimación registrada | G39: Sprint 7 | H39: Sprint 7 | I39: Sí | J39: 2026-09-30 | K39: Media | L39: HU-022 Web / UX ofertas | M39: Objetivo | N39: La UI conserva datos y estados reales del backend. • No recalcula ranking ni elegibilidad. • La vigencia usa expiresAt/estado entregado por la API. • Aceptar/rechazar continúa usando los endpoints existentes sin alterar la semántica transaccional. | O39: feat/web-offers-ux · commit eb3e35a · PR #139 · merge 8d276ac | P39: #139 | Q39: HU-035 (tarjeta Kanban) | R39: Modernización UX sobre el flujo Web existente; no agrega lógica paralela al motor de reasignación.
A40: HU-036 | B40: EP-12 Desktop institucional | C40: Como funcionario autorizado, quiero consultar desde Desktop el detalle de un proceso de reasignación, para supervisar candidatos, ofertas, política y trazabilidad sin alterar el proceso. | D40: Supervisar reasignaciones desde Desktop | E40: Done | F40: Sin estimación registrada | G40: Sprint 7 | H40: Sprint 7 | I40: Sí | J40: 2026-09-30 | K40: Alta | L40: HU-016 Desktop / reassignments.read | M40: Objetivo | N40: Consulta por UUID conocido con reassignments.read y contexto institucional. • Presenta resumen, política, evaluación, candidatos, ofertas y trazabilidad controlada. • Conserva orden/flags del backend. • No genera, acepta, rechaza, expira ni recalcula ofertas. | O40: feat/desktop-reassignment-supervision · commit 94770f9 · PR #141 · merge d5a5fe5 | P40: #141 | Q40: HU-036 (tarjeta Kanban) | R40: Supervisión Desktop read-only sobre HU-016, sin listado inventado ni inferencias de vigencia.
A41: HU-037 | B41: EP-12 Desktop institucional | C41: Como usuario institucional autorizado, quiero consultar indicadores y reportes desde CitaJusta Desktop, para analizar citas, recuperación de cupos y ofertas dentro de mi ámbito. | D41: Consultar reportes institucionales desde Desktop | E41: Done | F41: Sin estimación registrada | G41: Sprint 7 | H41: Sprint 7 | I41: Sí | J41: 2026-09-30 | K41: Media | L41: HU-019 Desktop / RF-037 | M41: Objetivo | N41: Requiere reports.read y contexto institucional. • Desde/Hasta son fechas civiles inclusivas de 1 a 366 días. • Sede, servicio y profesional son filtros opcionales. • Muestra los diez valores entregados por la API, incluidos ceros, sin inventar series, tendencias ni totales. | O41: feat/desktop-reports · commit 8d3bb26 · PR #143 · merge cb445ca | P41: #143 | Q41: HU-037 (tarjeta Kanban) | R41: Reportes Desktop consume GET /api/v1/reports/indicators; catálogos auxiliares no bloquean una consulta por período.
...

Sheet Épicas
A1: ÉPICAS DEL PRODUCT BACKLOG
A2: Fuente: 09_Epicas_Historias_Usuario v1.5 (MoSCoW). EP-14 se agrega en v2.0 para agrupar los PBI de cierre técnico del Sprint 9. Conteos con fórmulas sobre la hoja Product Backlog.
A4: ID | B4: Épica | C4: Elementos asociados | D4: MoSCoW | E4: Elementos Done | F4: Elementos totales
A5: EP-01 | B5: Cuenta y acceso | C5: HU-001, HU-002 | D5: Must | E5: =COUNTIFS('Product Backlog'!B:B,"EP-01 Cuenta y acceso",'Product Backlog'!E:E,"Done") -> 2 | F5: =COUNTIF('Product Backlog'!B:B,"EP-01 Cuenta y acceso") -> 2
A6: EP-02 | B6: Citas | C6: HU-003, HU-004, HU-005, HU-006, HU-026 | D6: Must | E6: =COUNTIFS('Product Backlog'!B:B,"EP-02 Citas",'Product Backlog'!E:E,"Done") -> 5 | F6: =COUNTIF('Product Backlog'!B:B,"EP-02 Citas") -> 5
A7: EP-03 | B7: Lista de espera | C7: HU-007, HU-008, HU-021 | D7: Must | E7: =COUNTIFS('Product Backlog'!B:B,"EP-03 Lista de espera",'Product Backlog'!E:E,"Done") -> 3 | F7: =COUNTIF('Product Backlog'!B:B,"EP-03 Lista de espera") -> 3
A8: EP-04 | B8: Agenda | C8: HU-014, HU-015 | D8: Must | E8: =COUNTIFS('Product Backlog'!B:B,"EP-04 Agenda",'Product Backlog'!E:E,"Done") -> 2 | F8: =COUNTIF('Product Backlog'!B:B,"EP-04 Agenda") -> 2
A9: EP-05 | B9: Administración | C9: HU-012, HU-013, HU-018 | D9: Must | E9: =COUNTIFS('Product Backlog'!B:B,"EP-05 Administración",'Product Backlog'!E:E,"Done") -> 3 | F9: =COUNTIF('Product Backlog'!B:B,"EP-05 Administración") -> 3
A10: EP-06 | B10: Reasignación | C10: HU-016, HU-025 | D10: Must | E10: =COUNTIFS('Product Backlog'!B:B,"EP-06 Reasignación",'Product Backlog'!E:E,"Done") -> 2 | F10: =COUNTIF('Product Backlog'!B:B,"EP-06 Reasignación") -> 2
A11: EP-07 | B11: Ofertas | C11: HU-009, HU-010, HU-011, HU-022, HU-023, HU-035 | D11: Must | E11: =COUNTIFS('Product Backlog'!B:B,"EP-07 Ofertas",'Product Backlog'!E:E,"Done") -> 6 | F11: =COUNTIF('Product Backlog'!B:B,"EP-07 Ofertas") -> 6
A12: EP-08 | B12: Operación | C12: HU-017 | D12: Should | E12: =COUNTIFS('Product Backlog'!B:B,"EP-08 Operación",'Product Backlog'!E:E,"Done") -> 1 | F12: =COUNTIF('Product Backlog'!B:B,"EP-08 Operación") -> 1
A13: EP-09 | B13: Reportes | C13: HU-019 | D13: Could | E13: =COUNTIFS('Product Backlog'!B:B,"EP-09 Reportes",'Product Backlog'!E:E,"Done") -> 1 | F13: =COUNTIF('Product Backlog'!B:B,"EP-09 Reportes") -> 1
A14: EP-10 | B14: Auditoría | C14: HU-020 | D14: Should | E14: =COUNTIFS('Product Backlog'!B:B,"EP-10 Auditoría",'Product Backlog'!E:E,"Done") -> 1 | F14: =COUNTIF('Product Backlog'!B:B,"EP-10 Auditoría") -> 1
A15: EP-11 | B15: Notificaciones | C15: HU-024 | D15: Must | E15: =COUNTIFS('Product Backlog'!B:B,"EP-11 Notificaciones",'Product Backlog'!E:E,"Done") -> 1 | F15: =COUNTIF('Product Backlog'!B:B,"EP-11 Notificaciones") -> 1
A16: EP-12 | B16: Desktop institucional | C16: HU-027, HU-028, HU-029, HU-030, HU-031, HU-032, HU-033, HU-034, HU-036, HU-037, HU-038 | D16: Must | E16: =COUNTIFS('Product Backlog'!B:B,"EP-12 Desktop institucional",'Product Backlog'!E:E,"Done") -> 11 | F16: =COUNTIF('Product Backlog'!B:B,"EP-12 Desktop institucional") -> 11
A17: EP-13 | B17: Integraciones externas | C17: HU-039, HU-040, HU-041, HU-042, HU-043, HU-044 | D17: Should | E17: =COUNTIFS('Product Backlog'!B:B,"EP-13 Integraciones externas",'Product Backlog'!E:E,"Done") -> 5 | F17: =COUNTIF('Product Backlog'!B:B,"EP-13 Integraciones externas") -> 6
A18: EP-14 | B18: Cierre técnico y calidad (nueva en v2.0) | C18: PBI-S9-01 a PBI-S9-10 | D18: Must | E18: =COUNTIFS('Product Backlog'!B:B,"EP-14 Cierre técnico y calidad (nueva en v2.0)",'Product Backlog'!E:E,"Done") -> 0 | F18: =COUNTIF('Product Backlog'!B:B,"EP-14 Cierre técnico y calidad (nueva en v2.0)") -> 10

Sheet Cambios de alcance
A1: REGISTRO DE CAMBIOS DE ALCANCE
A2: Cambios respecto del alcance original (Alcances v1.0/v1.1 y Documento Base) con su fecha, motivo y efecto en el backlog. Sólo se registran hechos documentados o verificables en git.
A4: N° | B4: Fecha | C4: Elemento | D4: Cambio | E4: Motivo / evidencia | F4: Efecto en el backlog | G4: Pendiente
A5: 1 | B5: 15-10-2026 | C5: HU-043 / RF-043 WhatsApp Cloud API | D5: Retirada del alcance entregable. | E5: Restricciones de facturación y verificación empresarial de Meta incompatibles con el contexto académico. Anexo 15-10 de Alcances; PR #169 (retiro documental). | F5: Estado "Excluida"; no cuenta como Done ni como pendiente. | G5: Issue #165 cerrada como COMPLETED: cambiar el motivo a "not planned". Reconciliar base local (PBI-S9-06).
A6: 2 | B6: 04-10-2026 (planificación) / 06-10-2026 (merge) | C6: HU-040 Google OAuth/OIDC | D6: Incorporada al Sprint 8 aunque Alcances §23 clasificaba la "integración con sistemas de identidad externos" como funcionalidad futura. | E6: Planificación de integraciones (PR #149, 04-10-2026); implementación PR #156. | F6: HU vigente y Done. | G6: No existía un registro de cambio de alcance equivalente al de HU-043; queda registrado aquí.
A7: 3 | B7: 04-10-2026 / 06-10-2026 | C7: HU-041 Google Calendar | D7: Incorporada al Sprint 8 aunque Alcances §23 clasificaba la "integración con calendarios externos" como futura. | E7: PR #149 (planificación); PR #159 (implementación). Copia puntual, sin sincronización bidireccional. | F7: HU vigente y Done. | G7: Ídem.
A8: 4 | B8: 17-10-2026 | C8: HU-044 Nager.Date (feriados de Chile) | D8: Integración fusionada antes de existir una HU en el backlog; se registra a posteriori. | E8: PR #174 (merge 865a7d0). El anexo 15-10 la describía como "idea no implementada". | F8: Nueva HU-044 en EP-13, estado Done con alcance de adaptador de sólo lectura. | G8: Definir HU futura para aplicar feriados a la disponibilidad (tipos que cierran atención, alcance regional).
A9: 5 | B9: 04-10-2026 | C9: Docker / Docker Compose | D9: Reprogramado del Sprint 2 (configuración técnica) al Sprint 9. | E9: Release Plan v1.10, R0.2: "Completar Docker/Docker Compose como parte del cierre técnico de Sprint 9". | F9: PBI-S9-01. | G9: Configuración preparada y verificada el 17-10-2026 (anexo Propuesta_Docker); pendiente de integración por el responsable del backend.
A10: 6 | B10: 04-10-2026 | C10: OpenAPI / Swagger, rate limiting y hardening | D10: Reprogramados del Sprint 3 (Documento Base) al Sprint 9. | E10: Release Plan v1.10, R0.3. | F10: PBI-S9-02 y PBI-S9-03. | G10: Pendientes.
A11: 7 | B11: 04-10-2026 | C11: Cantidad de Sprints | D11: De 8 Sprints (Documento Base: Sprint 8 = cierre) a 9 Sprints (Sprint 8 = integraciones, Sprint 9 = cierre). | E11: Release Plan v1.10; documentos anteriores conservan 8 Sprints. | F11: Sprint 9 con PBI propios. | G11: Mantener la referencia a 9 Sprints en los documentos nuevos.

Sheet Trazabilidad
A1: TRAZABILIDAD RF → HU → PR → PRUEBA
A2: Requisitos funcionales v0.2 y su cobertura. Pruebas: archivos de apps/*/test (unitarias, ejecutadas el 17-10-2026: API 691/691, Web 138/138, Desktop 165/165) y suites E2E sobre PostgreSQL real (17-10-2026: 236 pruebas, 234 pass).
A4: RF | B4: Requisito (resumen) | C4: HU | D4: Pull Request | E4: Pruebas / evidencia | F4: Cobertura
A5: RF-001 | B5: Registro de usuario final | C5: HU-001 | D5: #13 | E5: test/auth.service.test.mjs; E2E checkpoint 1/1; prueba de humo Docker | F5: Cubierto
A6: RF-002 | B6: Iniciar y cerrar sesión de forma segura | C6: HU-002, HU-040 | D6: #13, #14, #156 | E6: auth.service.test, access-token.guard.test, auth.google.test; E2E google 12/12 | F6: Cubierto
A7: RF-003 | B7: Recuperar acceso a la cuenta | C7: — | D7: — | E7: — | F7: No implementado (alcance Objetivo)
A8: RF-004 | B8: Consultar/actualizar perfil y preferencias de notificación | C8: HU-002 (GET /users/me), HU-040 (vinculación en /cuenta) | D8: #14, #156 | E8: users.me.test; web google-auth.test | F8: Parcial: consulta de perfil; sin edición ni preferencias
A9: RF-005 | B9: Registrar y administrar instituciones | C9: HU-012 | D9: #68 | E9: institutions.catalog.test | F9: Parcial: lectura de instituciones; sin alta/edición
A10: RF-006 | B10: Administrar sedes | C10: HU-012, HU-029 | D10: #68, #118 | E10: catalog-administration(-read).test; E2E catalog 15/15; desktop catalog.test | F10: Cubierto
A11: RF-007 | B11: Administrar servicios | C11: HU-012, HU-029 | D11: #68, #118 | E11: catalog-administration.test; E2E catalog 15/15 | F11: Cubierto
A12: RF-008 | B12: Registrar profesionales y asociarlos | C12: HU-013, HU-030 | D12: #71, #123 | E12: professional-administration(-read).test; E2E professionals 15/15; desktop professionals.test | F12: Cubierto
A13: RF-009 | B13: Configurar disponibilidad e indisponibilidades | C13: HU-014, HU-032, HU-044 | D13: #74, #129, #174 | E13: availability-administration(-read).test; E2E availability-admin 17/17; nager-date-holidays.test | F13: Cubierto (feriados: sólo consulta)
A14: RF-010 | B14: Consultar agenda por filtros | C14: HU-015, HU-031 | D14: #76, #126 | E14: agenda.test; E2E agenda 11/11; desktop agenda(-ui).test | F14: Cubierto
A15: RF-011 / RF-012 | B15: Buscar citas y mostrar cupos compatibles | C15: HU-003, HU-026 | D15: #16–#18, #43, #107 | E15: availability.catalog.test; web search-selection.test | F15: Cubierto
... A36: RF-043 | B36: WhatsApp Cloud API | C36: HU-043 | D36: #169 (retiro) | E36: — | F36: Excluido del alcance

Sheet Notas de versión
A1: NOTAS DE VERSIÓN — v1.10 → v2.0
A2: Versión 2.0 · 17-10-2026 · Equipo CitaJusta
A4: Tipo | B4: Cambio
A5: Estado | B5: HU-001 a HU-042 se mantienen Done con verificación git; HU-043 pasa de "Fuera de alcance" a "Excluida (15-10-2026)".
A6: Nueva HU | B6: HU-044 "Consultar feriados de Chile mediante Nager.Date", registrada a posteriori (PR #174 del 17-10-2026).
A7: Nuevos PBI | B7: PBI-S9-01 a PBI-S9-10 del Sprint 9 (cierre técnico y académico) bajo la nueva épica EP-14.
A8: Nuevas columnas | B8: Sprint de integración según fecha de merge, coincidencia plan/integración, fecha de merge, Pull Request, Observación v2.0.
A9: Correcciones | B9: Se agregan los PR omitidos en v1.10 (#118, #123, #126, #129, #133) y se explicita que HU-005 no tuvo PR (commit 89d15a8).
A10: Correcciones | B10: Issue de HU-039 a HU-042: v1.10 indicaba "Pendiente de crear/refinar" mientras citaba Issues cerrados; v2.0 registra #152, #155, #158 y #162.
A11: Correcciones | B11: HU-042 figuraba como "implementación local" en el anexo 15-10; el PR #163 se fusionó el 08-10-2026.
A12: Correcciones | B12: La mejora Resend V2 figuraba "sin commit/PR"; quedó fusionada el 17-10-2026 (PR #173). Su validación en Gmail pasa a PBI-S9-07.
A13: Correcciones | B13: "Historias Objetivo 21" de v1.10 incluía HU-043 excluida; los conteos de v2.0 la separan.
A14: Normalización | B14: La columna Épica usa el código EP-xx del documento 09 (por ejemplo HU-023 y HU-035 → EP-07 Ofertas; HU-038 → EP-12).
A15: Métrica | B15: Se agrega el avance derivado del backlog: 100 % por HU vigentes y 81,1 % incluyendo los PBI de cierre técnico (Resumen).
A16: Conservado | B16: Redacción de historias, criterios de aceptación, prioridades, RF, alcance y Story Points de la v1.10 sin cambios. Las hojas históricas "Actualización 15-10" y "Corte GitHub 16-10" permanecen en el archivo v1.10.
